<mujoco model="simplethrustboxtZ0">
	<compiler angle="degree" coordinate="local" inertiafromgeom="true"/>
	<option timestep="0.01" gravity="0 0 0" density="1" viscosity="0" integrator="RK4"/>
	<visual>
		<map force="0.1" zfar="30"/>
		<rgba haze="0.15 0.25 0.35 1"/>
		<global offwidth="2560" offheight="1440" elevation="-20" azimuth="120"/>
	</visual>
	<default>
		<joint armature="1" damping="1" limited="true"/>
		<geom conaffinity="1" condim="1" density="5.0" friction="1 0.5 0.5" margin="0.01" rgba="0.8 0.6 0.4 1"/>
		<default class="shoulder">
			<joint pos="0.0 0.0 0.0" stiffness="100" range="30 70" springref="70"/>
		</default>
		<default class="armgeom">
			<geom size="0.08" type="capsule" rgba="1 .6 0 1"/>
		</default>
		<default class="elbow">
			<joint pos="0.0 0.0 0.0" stiffness="100" range="30 70" springref="70"/>
		</default>
		<default class="thruster">
			<site type="cylinder" size="0.02 0.05" rgba="0.3 0.8 0.3 1" quat="1.0 0.0 0.0 0."/>
		</default>
	</default>
	<!-- 	<default class = "elbow">
		<geom  type="capsule"/>
	</default> -->
	<asset>
		<texture type="skybox" builtin="gradient" rgb1=".3 .5 .7" rgb2="0 0 0" width="32" height="512"/>
	</asset>
	<worldbody>
		<!-- <geom name="floor" pos = "0 0 0" size="2 2 .125" type="plane" conaffinity="1" condim="3"/> -->
		<!-- Satellite -->
		<body name="box" pos="0 0 1">
			<geom name="core" pos="0 0 0" quat="1 0 0 0" size=".2 .2 .2" type="box" rgba="0.3 0.3 0.8 .5" mass=".1"/>
			<joint name="root" type="free" damping="0" armature="0" pos="0 0 0"/>
			<site name="IMUmount" pos="0.0 0.0 0.0" type="sphere" size="0.02" quat="1.0 0.0 0.0 0." rgba="1 1 1 1"/>

			<!-- thruster colors determined by xyz->rgb where +x,+y,+z is r=1,b=1,g=1 and -x,-y,-z is r=0,b=0,g=0 -->
			<!-- Thruster geoms -->
			<site name="motorX" fromto="-.1  .0  .0  .1  .0  .0" class="thruster" rgba="1 0 0 1"/>
			<site name="motorY" fromto=" .0 -.1  .0  .0  .1  .0" class="thruster" rgba="0 1 0 1"/>
			<site name="motorZ" fromto=" .0  .0 -.1  .0  .0  .1" class="thruster" rgba="0 0 1 1"/>
			
			<!-- Visualization of the coordinate frame-->
			<site name="qcX" type="box" pos="0.2 0.0 0.0" size="0.2 0.005 0.005" quat=" 1.000  0.0  0.0    0." rgba="1 0 0 1"/>
			<site name="qcY" type="box" pos="0.0 0.2 0.0" size="0.2 0.005 0.005" quat=" 0.707  0.0  0.0    0.707" rgba="0 1 0 1"/>
			<site name="qcZ" type="box" pos="0.0 0.0 0.2" size="0.2 0.005 0.005" quat="-0.707  0.0  0.707  0." rgba="0 0 1 1"/>
			<!--
			<site name="motor0" type="cylinder" size="0.1 0.05"  fromto = ".0 0 .2 .0 .0 .25"quat = "1.0 0.0 0.0 0." rgba="0.3 0.8 0.3 1"/>
			<site name="motor1" type="cylinder" size="0.1 0.05"  fromto = ".0 .2 .0 .0 .25 .0"  quat = "1.0 0.0 0.0 0." rgba="0.3 0.8 0.3 1"/>
			<site name="motor2" type="cylinder" size="0.1 0.05"  fromto = ".2 .0 .0 .25 0 .0"  quat = "1.0 0.0 0.0 0." rgba="0.3 0.8 0.3 1"/>
			<site name="motor3" type="cylinder" size="0.1 0.05"  fromto = "0 -.2 .0 .0 -.25 .0"  quat = "1.0 0.0 0.0 0." rgba="0.3 0.8 0.3 1"/>
			<site name="motor4" type="cylinder" size="0.1 0.05"  fromto = "-.2 .0 .0 -.25 0 .0"  quat = "1.0 0.0 0.0 0." rgba="0.3 0.8 0.3 1"/>
			-->
			<!-- 			<body name="left_arm" pos="0 0 0">
				<geom fromto="0.0 0.0 -0.18 0.2 0 -0.18" name="aux_1_geom" class ="armgeom"/> -->
		</body>
		<!-- Target -->
		<body name="target" pos=".1 -.1 .01">
			<camera name = "camera1" mode = "targetbodycom" target = "world" pos="2.370 -2.859 2.423" xyaxes="0.770 0.638 0.000 -0.228 0.275 0.934"/>
			<joint armature="0" axis="1 0 0" damping="0" limited="true" name="target_x" pos="0 0 0" range="-3 3" ref="0" stiffness="0" type="slide"/>
			<joint armature="0" axis="0 1 0" damping="0" limited="true" name="target_y" pos="0 0 0" range="-3 3" ref="0" stiffness="0" type="slide"/>
			<joint armature="0" axis="0 0 1" damping="0" limited="true" name="target_z" pos="0 0 0" range="-3 3" ref="0" stiffness="0" type="slide"/>
			<geom conaffinity="0" contype="0" name="target" pos="0 0 0" rgba="0.9 0.2 0.2 1" size=".05" type="sphere" mass=".1"/>

		</body>
	</worldbody>
	<actuator>
		<motor name="ForceX" ctrllimited="true" ctrlrange="-1. 1.0" gear=".0  .0 -.2  0. 0. 0." site="motorX"/>
		<motor name="ForceY" ctrllimited="true" ctrlrange="-1. 1.0" gear=".0  .0 -.2  0. 0. 0." site="motorY"/>
		<motor name="ForceZ" ctrllimited="true" ctrlrange="-1. 1.0" gear=".0  .0 -.2  0. 0. 0." site="motorZ"/>
		
		<motor name="TorqueX" ctrllimited="true" ctrlrange="-1. 1.0" gear=".0  .0 .0  0. 0. -.01" site="motorX"/>
		<motor name="TorqueY" ctrllimited="true" ctrlrange="-1. 1.0" gear=".0  .0 .0  0. 0. -.01" site="motorY"/>
		<motor name="TorqueZ" ctrllimited="true" ctrlrange="-1. 1.0" gear=".0  .0 .0  0. 0. -.01" site="motorZ"/>
	</actuator>
	
	<sensor>
		<accelerometer name="accel" site = "IMUmount"/>
		<gyro name="gyro" site = "IMUmount"/>
	</sensor>
</mujoco>
 